Workbook
Name Customer_behavior: Table1[]
Name DynamicData: OFFSET([1]ecommerce_customer_behavior_dat!$A$1,0,0,COUNTA([1]ecommerce_customer_behavior_dat!$A:$A),18)
Name Slicer_City: #N/A
Name Slicer_Gender: #N/A
Name Slicer_Product_Category: #N/A

Sheet DashBoard
C59: Enter Order ID | G59: ORD_001337
C61: Customer Name | G61: =IFERROR(INDEX(Table1[Customer_ID], MATCH(DashBoard!G59, Table1[Order_ID], 0)), "-") -> CUST_01337
C63: City | G63: =IFERROR(INDEX(Table1[City], MATCH(DashBoard!G59, Table1[Order_ID], 0)), "-") -> Bursa
C65: Amount | G65: =IFERROR(INDEX(Table1[Total_Amount], MATCH(DashBoard!G59, Table1[Order_ID], 0)), "-") -> 54.28
C67: Category | G67: =IFERROR(INDEX(Table1[Product_Category], MATCH(DashBoard!G59, Table1[Order_ID], 0)), "-") -> Toys

Sheet Data
A1: Order_ID | B1: Customer_ID | C1: Date | D1: Day_Name | E1: Age | F1: Age Group | G1: Gender | H1: City | I1: Product_Category | J1: Unit_Price | K1: Quantity | L1: Discount_Amount | M1: Total_Amount | N1: Payment_Method | O1: Device_Type | P1: Session_Duration_Minutes | Q1: Pages_Viewed | R1: Is_Returning_Customer | S1: Delivery_Time_Days | T1: Customer_Rating
A2: ORD_001337 | B2: CUST_01337 | C2: 44927 | D2: =TEXT(C2, "dddd") -> Sunday | E2: 25 | F2: =IFERROR(IF(E2<25, "Gen Z", IF(E2<45, "Millennials", "Gen X/Boomers")),"Not Valide Age") -> Millennials | G2: Female | H2: Bursa | I2: Toys | J2: 54.28 | K2: 1 | L2: 0 | M2: 54.28 | N2: Debit Card | O2: Mobile | P2: 4 | Q2: 14 | R2: TRUE | S2: 8 | T2: 5
A3: ORD_004885 | B3: CUST_04885 | C3: 44927 | D3: =TEXT(C3, "dddd") -> Sunday | E3: 42 | F3: =IFERROR(IF(E3<25, "Gen Z", IF(E3<45, "Millennials", "Gen X/Boomers")),"Not Valide Age") -> Millennials | G3: Male | H3: Konya | I3: Toys | J3: 244.9 | K3: 1 | L3: 0 | M3: 244.9 | N3: Credit Card | O3: Mobile | P3: 11 | Q3: 3 | R3: TRUE | S3: 3 | T3: 3
A4: ORD_004507 | B4: CUST_04507 | C4: 44927 | D4: =TEXT(C4, "dddd") -> Sunday | E4: 43 | F4: =IFERROR(IF(E4<25, "Gen Z", IF(E4<45, "Millennials", "Gen X/Boomers")),"Not Valide Age") -> Millennials | G4: Female | H4: Ankara | I4: Food | J4: 48.15 | K4: 5 | L4: 0 | M4: 240.75 | N4: Credit Card | O4: Mobile | P4: 7 | Q4: 8 | R4: TRUE | S4: 5 | T4: 2
A5: ORD_000645 | B5: CUST_00645 | C5: 44927 | D5: =TEXT(C5, "dddd") -> Sunday | E5: 32 | F5: =IFERROR(IF(E5<25, "Gen Z", IF(E5<45, "Millennials", "Gen X/Boomers")),"Not Valide Age") -> Millennials | G5: Male | H5: Istanbul | I5: Electronics | J5: 804.06 | K5: 1 | L5: 229.28 | M5: 574.78 | N5: Credit Card | O5: Mobile | P5: 8 | Q5: 10 | R5: FALSE | S5: 1 | T5: 4
A6: ORD_000690 | B6: CUST_00690 | C6: 44927 | D6: =TEXT(C6, "dddd") -> Sunday | E6: 40 | F6: =IFERROR(IF(E6<25, "Gen Z", IF(E6<45, "Millennials", "Gen X/Boomers")),"Not Valide Age") -> Millennials | G6: Female | H6: Istanbul | I6: Sports | J6: 755.61 | K6: 5 | L6: 0 | M6: 3778.05 | N6: Cash on Delivery | O6: Desktop | P6: 21 | Q6: 10 | R6: TRUE | S6: 7 | T6: 4
A7: ORD_000223 | B7: CUST_00223 | C7: 44927 | D7: =TEXT(C7, "dddd") -> Sunday | E7: 43 | F7: =IFERROR(IF(E7<25, "Gen Z", IF(E7<45, "Millennials", "Gen X/Boomers")),"Not Valide Age") -> Millennials | G7: Female | H7: Istanbul | I7: Beauty | J7: 122.46 | K7: 1 | L7: 0 | M7: 122.46 | N7: Credit Card | O7: Mobile | P7: 14 | Q7: 9 | R7: TRUE | S7: 9 | T7: 5
A8: ORD_002506 | B8: CUST_02506 | C8: 44927 | D8: =TEXT(C8, "dddd") -> Sunday | E8: 25 | F8: =IFERROR(IF(E8<25, "Gen Z", IF(E8<45, "Millennials", "Gen X/Boomers")),"Not Valide Age") -> Millennials | G8: Female | H8: Izmir | I8: Electronics | J8: 2107.37 | K8: 2 | L8: 0 | M8: 4214.74 | N8: Digital Wallet | O8: Desktop | P8: 10 | Q8: 5 | R8: FALSE | S8: 6 | T8: 5
A9: ORD_004540 | B9: CUST_04540 | C9: 44927 | D9: =TEXT(C9, "dddd") -> Sunday | E9: 44 | F9: =IFERROR(IF(E9<25, "Gen Z", IF(E9<45, "Millennials", "Gen X/Boomers")),"Not Valide Age") -> Millennials | G9: Male | H9: Konya | I9: Food | J9: 213.64 | K9: 2 | L9: 0 | M9: 427.28 | N9: Credit Card | O9: Mobile | P9: 10 | Q9: 16 | R9: FALSE | S9: 3 | T9: 5
A10: ORD_001808 | B10: CUST_01808 | C10: 44928 | D10: =TEXT(C10, "dddd") -> Monday | E10: 41 | F10: =IFERROR(IF(E10<25, "Gen Z", IF(E10<45, "Millennials", "Gen X/Boomers")),"Not Valide Age") -> Millennials | G10: Male | H10: Istanbul | I10: Fashion | J10: 257.62 | K10: 5 | L10: 62.15 | M10: 1225.95 | N10: Credit Card | O10: Tablet | P10: 24 | Q10: 7 | R10: FALSE | S10: 2 | T10: 4
A11: ORD_003413 | B11: CUST_03413 | C11: 44928 | D11: =TEXT(C11, "dddd") -> Monday | E11: 58 | F11: =IFERROR(IF(E11<25, "Gen Z", IF(E11<45, "Millennials", "Gen X/Boomers")),"Not Valide Age") -> Gen X/Boomers | G11: Male | H11: Istanbul | I11: Sports | J11: 1784.75 | K11: 4 | L11: 490.25 | M11: 6648.75 | N11: Debit Card | O11: Desktop | P11: 8 | Q11: 5 | R11: TRUE | S11: 5 | T11: 4
A12: ORD_004457 | B12: CUST_04457 | C12: 44928 | D12: =TEXT(C12, "dddd") -> Monday | E12: 21 | F12: =IFERROR(IF(E12<25, "Gen Z", IF(E12<45, "Millennials", "Gen X/Boomers")),"Not Valide Age") -> Gen Z | G12: Female | H12: Istanbul | I12: Electronics | J12: 1091.11 | K12: 1 | L12: 0 | M12: 1091.11 | N12: Cash on Delivery | O12: Mobile | P12: 9 | Q12: 6 | R12: TRUE | S12: 3 | T12: 4
A13: ORD_004797 | B13: CUST_04797 | C13: 44928 | D13: =TEXT(C13, "dddd") -> Monday | E13: 40 | F13: =IFERROR(IF(E13<25, "Gen Z", IF(E13<45, "Millennials", "Gen X/Boomers")),"Not Valide Age") -> Millennials | G13: Male | H13: Konya | I13: Beauty | J13: 77.06 | K13: 2 | L13: 15.22 | M13: 138.9 | N13: Credit Card | O13: Mobile | P13: 5 | Q13: 6 | R13: FALSE | S13: 4 | T13: 3
... A566: ORD_000552 | B566: CUST_00552 | C566: 44979 | D566: =TEXT(C566, "dddd") -> Wednesday | E566: 33 | F566: =IFERROR(IF(E566<25, "Gen Z", IF(E566<45, "Millennials", "Gen X/Boomers")),"Not Valide Age") -> Millennials | G566: Male | H566: Ankara | I566: Electronics | J566: 2717.55 | K566: 4 | L566: 0 | M566: 10870.2 | N566: Digital Wallet | O566: Mobile | P566: 8 | Q566: 7 | R566: TRUE | S566: 7 | T566: 5

Sheet Analysis
A1: Summary Table
A4: Count of Order_ID | B4: Average of Customer_Rating | C4: Sum of Total_Amount
A5: 263 | B5: 3.9467681 | C5: 258480.27
A8: Customer Demographic & Spending
A12: Row Labels | B12: Average of Session_Duration_Minutes | C12: Sum of Total_Amount
A13: Gen X/Boomers | B13: 12.296296 | C13: 67035.9
A14: Gen Z | B14: 16.632653 | C14: 43405.1
A15: Millennials | B15: 14.325 | C15: 148039.27
A16: Grand Total | B16: 14.338403 | C16: 258480.27
A28: Geographical & Product Insights
A31: Row Labels | B31: Sum of Total_Amount
A32: Adana | B32: 9002.97 | D32: City | E32: Total Amount
A33: Ankara | B33: 32274.91 | D33: Adana | E33: 22418.36
A34: Antalya | B34: 23303.61 | D34: Ankara | E34: 71945.13
A35: Bursa | B35: 27658.25 | D35: Antalya | E35: 34913.38
A36: Eskisehir | B36: 14863.73 | D36: Bursa | E36: 46677.76
A37: Gaziantep | B37: 18674.98 | D37: Eskisehir | E37: 18062.72
A38: Istanbul | B38: 71179.85 | D38: Gaziantep | E38: 49473.52
A39: Izmir | B39: 24375.86 | D39: Istanbul | E39: 167389.57
A40: Kayseri | B40: 10427.48 | D40: Izmir | E40: 72597.07
A41: Konya | B41: 26718.63 | D41: Kayseri | E41: 31742.19
A42: Grand Total | B42: 258480.27 | D42: Konya | E42: 45165.98
D43: Grand Total | E43: 560385.68
A53: Payment Method Analysis
A57: Row Labels | B57: Count of Order_ID
A58: Bank Transfer | B58: 28
A59: Cash on Delivery | B59: 15
A60: Credit Card | B60: 109
A61: Debit Card | B61: 59
A62: Digital Wallet | B62: 52
A63: Grand Total | B63: 263
A69: Total Product Sale
A72: Row Labels | B72: Sum of Total_Amount
A73: Beauty | B73: 6104.03
A74: Books | B74: 3007.45
A75: Electronics | B75: 125871.37
A76: Fashion | B76: 14785.91
A77: Food | B77: 5478.16
A78: Home & Garden | B78: 44427.41
A79: Sports | B79: 48987.44
...

Sheet Raw Data
A1: Order_ID | B1: Customer_ID | C1: Date | D1: Age | E1: Gender | F1: City | G1: Product_Category | H1: Unit_Price | I1: Quantity | J1: Discount_Amount | K1: Total_Amount | L1: Payment_Method | M1: Device_Type | N1: Session_Duration_Minutes | O1: Pages_Viewed | P1: Is_Returning_Customer | Q1: Delivery_Time_Days | R1: Customer_Rating
A2: ORD_001337 | B2: CUST_01337 | C2: 44927 | D2: 27 | E2: Female | F2: Bursa | G2: Toys | H2: 54.28 | I2: 1 | J2: 0 | K2: 54.28 | L2: Debit Card | M2: Mobile | N2: 4 | O2: 14 | P2: TRUE | Q2: 8 | R2: 5
A3: ORD_004885 | B3: CUST_04885 | C3: 44927 | D3: 42 | E3: Male | F3: Konya | G3: Toys | H3: 244.9 | I3: 1 | J3: 0 | K3: 244.9 | L3: Credit Card | M3: Mobile | N3: 11 | O3: 3 | P3: TRUE | Q3: 3 | R3: 3
A4: ORD_004507 | B4: CUST_04507 | C4: 44927 | D4: 43 | E4: Female | F4: Ankara | G4: Food | H4: 48.15 | I4: 5 | J4: 0 | K4: 240.75 | L4: Credit Card | M4: Mobile | N4: 7 | O4: 8 | P4: TRUE | Q4: 5 | R4: 2
A5: ORD_000645 | B5: CUST_00645 | C5: 44927 | D5: 32 | E5: Male | F5: Istanbul | G5: Electronics | H5: 804.06 | I5: 1 | J5: 229.28 | K5: 574.78 | L5: Credit Card | M5: Mobile | N5: 8 | O5: 10 | P5: FALSE | Q5: 1 | R5: 4
A6: ORD_000690 | B6: CUST_00690 | C6: 44927 | D6: 40 | E6: Female | F6: Istanbul | G6: Sports | H6: 755.61 | I6: 5 | J6: 0 | K6: 3778.05 | L6: Cash on Delivery | M6: Desktop | N6: 21 | O6: 10 | P6: TRUE | Q6: 7 | R6: 4
A7: ORD_000223 | B7: CUST_00223 | C7: 44927 | D7: 43 | E7: Female | F7: Istanbul | G7: Beauty | H7: 122.46 | I7: 1 | J7: 0 | K7: 122.46 | L7: Credit Card | M7: Mobile | N7: 14 | O7: 9 | P7: TRUE | Q7: 9 | R7: 5
A8: ORD_002506 | B8: CUST_02506 | C8: 44927 | D8: 25 | E8: Female | F8: Izmir | G8: Electronics | H8: 2107.37 | I8: 2 | J8: 0 | K8: 4214.74 | L8: Digital Wallet | M8: Desktop | N8: 10 | O8: 5 | P8: FALSE | Q8: 6 | R8: 5
A9: ORD_004540 | B9: CUST_04540 | C9: 44927 | D9: 44 | E9: Male | F9: Konya | G9: Food | H9: 213.64 | I9: 2 | J9: 0 | K9: 427.28 | L9: Credit Card | M9: Mobile | N9: 10 | O9: 16 | P9: FALSE | Q9: 3 | R9: 5
A10: ORD_001808 | B10: CUST_01808 | C10: 44928 | D10: 41 | E10: Male | F10: Istanbul | G10: Fashion | H10: 257.62 | I10: 5 | J10: 62.15 | K10: 1225.95 | L10: Credit Card | M10: Tablet | N10: 24 | O10: 7 | P10: FALSE | Q10: 2 | R10: 4
A11: ORD_003413 | B11: CUST_03413 | C11: 44928 | D11: 58 | E11: Male | F11: Istanbul | G11: Sports | H11: 1784.75 | I11: 4 | J11: 490.25 | K11: 6648.75 | L11: Debit Card | M11: Desktop | N11: 8 | O11: 5 | P11: TRUE | Q11: 5 | R11: 4
A12: ORD_004457 | B12: CUST_04457 | C12: 44928 | D12: 21 | E12: Female | F12: Istanbul | G12: Electronics | H12: 1091.11 | I12: 1 | J12: 0 | K12: 1091.11 | L12: Cash on Delivery | M12: Mobile | N12: 9 | O12: 6 | P12: TRUE | Q12: 3 | R12: 4
A13: ORD_004797 | B13: CUST_04797 | C13: 44928 | D13: 40 | E13: Male | F13: Konya | G13: Beauty | H13: 77.06 | I13: 2 | J13: 15.22 | K13: 138.9 | L13: Credit Card | M13: Mobile | N13: 5 | O13: 6 | P13: FALSE | Q13: 4 | R13: 3
... A566: ORD_000552 | B566: CUST_00552 | C566: 44979 | D566: 33 | E566: Male | F566: Ankara | G566: Electronics | H566: 2717.55 | I566: 4 | J566: 0 | K566: 10870.2 | L566: Digital Wallet | M566: Mobile | N566: 8 | O566: 7 | P566: TRUE | Q566: 7 | R566: 5

Sheet Calculation
A1: =SUM(Data!M:M) -> 560385.68 | B1: Sum Total-Amount
A2: =AVERAGE(Data!T:T) -> 3.9168142 | B2: Avg_Rating
A3: =COUNTA(Data!A:A) -> 566 | B3: Count_orderID
A4: =AVERAGE(Table1[Session_Duration_Minutes]) -> 14.753982 | B4: avg _Session
